Workbook

Sheet stream compositions
A1: F1 | B1: air
A4: F2 | B4: recycle
A7: F3 | B7: IB
A10: F4 | B10: steam
B13: basis be 100 kmols in feed
B14: Stream 4 | C14: mol% | D14: kmol/h | E14: mw | F14: kg/h
A15: PG1 | B15: IB | C15: =D15/$D$19*100 -> 8.627451 | D15: 41.75 | E15: 56 | F15: =D15*E15 -> 2338
B16: O2 | C16: =D16/$D$19*100 -> 17.254902 | D16: =D15*2 -> 83.5 | E16: 32 | F16: =D16*E16 -> 2672
B17: N2 | C17: =D17/$D$19*100 -> 61.176471 | D17: =D16*0.78/0.22 -> 296.04545 | E17: 28 | F17: =D17*E17 -> 8289.2727
B18: steam | C18: =D18/$D$19*100 -> 12.941176 | D18: =D15*1.5 -> 62.625 | E18: 18 | F18: =D18*E18 -> 1127.25
B19: Total | D19: =SUM(D15:D18) -> 483.92045 | F19: =SUM(F15:F18) -> 14426.523 | J19: =3.98*0.796 -> 3.16808
B20: conv | C20: 0.996 | E20: =0.796 -> 0.796
C21: mol% | D21: kmol/h | E21: mw | F21: kg/h | H21: moles of steam + co2
A22: PG2 | B22: IB | C22: =250*10^-6*10^2 -> 0.025 | D22: =D15*(1-C20) -> 0.167 | E22: 56 | F22: =D22*E22 -> 9.352 | H22: =D36-SUM(D22:D33) -> 327.66789
A23: 300 deg C | B23: MAC | C23: 4.8 | D23: =D15*E20 -> 33.233 | E23: 70 | F23: =D23*E23 -> 2326.31
B24: CO | C24: 0.74 | D24: =$D$36*C24% -> 5.1234208 | E24: 28 | F24: =D24*E24 -> 143.45578 | H24: mass of steam + co2
B25: MAA | C25: 0.21 | D25: =$D$36*C25% -> 1.4539438 | E25: 86 | F25: =D25*E25 -> 125.03916 | H25: =F36-SUM(F22:F33) -> 2521.5636
B26: Acetic ac | C26: 0.21 | D26: =$D$36*C26% -> 1.4539438 | E26: 60 | F26: =D26*E26 -> 87.236625
B27: acetone | C27: 0.12 | D27: =$D$36*C27% -> 0.830825 | E27: 58 | F27: =D27*E27 -> 48.18785 | H27: 1 | I27: 1 | J27: =H22 -> 327.66789
B28: acetalde | C28: 0.21 | D28: =$D$36*C28% -> 1.4539438 | E28: 44 | F28: =D28*E28 -> 63.973525 | H28: 44 | I28: 18 | J28: =H25 -> 2521.5636
B29: acrolein | C29: 0.04 | D29: =$D$36*C29% -> 0.27694167 | E29: 56 | F29: =D29*E29 -> 15.508733
B30: formaldehyde | C30: 0.03 | D30: =$D$36*C30% -> 0.20770625 | E30: 30 | F30: =D30*E30 -> 6.2311875 | H30: {=MMULT(MINVERSE(H27:I28),J27:J28)} -> -129.86378
B31: acrylic acid | C31: 0.03 | D31: =$D$36*C31% -> 0.20770625 | E31: 72 | F31: =D31*E31 -> 14.95485 | H31: 457.53167
B32: oxygen | C32: 3.5 | D32: =$D$36*C32% -> 24.232396 | E32: 32 | F32: =D32*E32 -> 775.43667
B33: nitrogen | C33: =D33/$D$36*100 -> 42.759251 | D33: =D17 -> 296.04545 | E33: 28 | F33: =D33*E33 -> 8289.2727
B34: CO2 | C34: =D34/$D$36*100 -> -18.756843 | D34: =H30 -> -129.86378 | E34: 44 | F34: =D34*E34 -> -5714.0064
B35: steam | C35: =D35/$D$36*100 -> 66.083471 | D35: =H31 -> 457.53167 | E35: 18 | F35: =D35*E35 -> 8235.57
B36: total | C36: =SUM(C22:C35) -> 100.00088 | D36: =D23/C23% -> 692.35417 | F36: =F19 -> 14426.523
F37: =SUM(F22:F35) -> 14426.523
A38: PG3 | B38: PG2 + PG6 | H38: 1.41 mol% of an organic component containing 1.2 mol% of methacrolein, 0.03 mol% of methacrylic acid, 0.09 mol% of acetone, 0.05 mol% of acetaldehyde, 0.04 mol% of acrolein, and 17 mol% of oxygen and 13 mol% of water.
A40: PG6 | C40: mol% | D40: kmol/h | E40: mw | F40: kg/h
A41: 80 deg C | B41: MAC | C41: 1.2
B42: MAA | C42: 0.03
B43: acetone | C43: 0.09
B44: acetaldehyde | C44: 0.05
B45: acrolein | C45: 0.04
B46: oxygen | C46: 17
B47: steam | C47: 13
B48: N2 | C48: =100-SUM(C41:C47) -> 68.59
A50: PG3 | B50: IB | C50: 0 | H50: 3.44 mol% methacrolein, 0.31 mol% CO, 0.12 mol% methacrylic acid, 0.12 mol% acetic acid, 0.15 mol% acetone, 0.15 mol% acetaldehyde, 0.06 mol% acrolein, 0.02 mol% formaldehyde and 0.01 mol% acrylic acid.
...

Sheet heat of reactions
E1: A | F1: B | G1: C | H1: LR | J1: LR species | K1: A | L1: B | M1: C | N1: Tr1 | O1: H_rxn atTr1 | P1: Tr_2 | Q1: H_rxn at Tr2
A2: IB + O2 → Acetone + Formaldehyde | E2: =C25+C20-C31 -> -312.972 | F2: =D25+D20-D31 -> -0.013009 | G2: =E25+E20-E31 -> 3.7847e-06 | H2: acetone | J2: =H2 -> acetone | K2: =E2 -> -312.972 | L2: =F2 -> -0.013009 | M2: =G2 -> 3.7847e-06 | N2: =350+273.15 -> 623.15 | O2: =$K2+$L2*N2+$M2*N2^2 -> -319.6089 | P2: =302+273.15 -> 575.15 | Q2: =$K2+$L2*P2+$M2*P2^2 -> -319.20216
A3: MAC +3O2 → Acetic acid + CO2 + H2O | E3: =C21+C19-C26+C29 -> -963.534 | F3: =D21+D19-D26+D29 -> -4.7606959 | G3: =E21+E19-E26+E29 -> -2.80879e-05 | H3: acetic acid | J3: =H3 -> acetic acid | K3: =E3 -> -963.534 | L3: =F3 -> -4.7606959 | M3: =G3 -> -2.80879e-05 | N3: =350+273.15 -> 623.15 | O3: =$K3+$L3*N3+$M3*N3^2 -> -3941.0686 | P3: =302+273.15 -> 575.15 | Q3: =$K3+$L3*P3+$M3*P3^2 -> -3710.9396
A4: MAC + 2O2 → Acryclic acid + H2O | E4: =C24+C29-C26 -> -472.566 | F4: =D24+D29-D26 -> 0.030496 | G4: =E24+E29-E26 -> -2.91374e-05 | H4: acry | J4: =H4 -> acry | K4: =E4 -> -472.566 | L4: =F4 -> 0.030496 | M4: =G4 -> -2.91374e-05 | N4: =350+273.15 -> 623.15 | O4: =$K4+$L4*N4+$M4*N4^2 -> -464.87693 | P4: =302+273.15 -> 575.15 | Q4: =$K4+$L4*P4+$M4*P4^2 -> -464.66481
A5: IB + 2.5 O2 → Acroelin + CO2 + 2H2O | E5: =C23+C19+2*C29-C31 -> -941.07 | F5: =D23+D19+2*D29-D31 -> -0.00221387 | G5: =E23+E19+2*E29-E31 -> 6.2337e-06 | H5: acro | J5: =H5 -> acro | K5: =E5+E6 -> -1548.722 | L5: =F5+F6 -> 0.01301226 | M5: =G5+G6 -> -6.5082e-06 | N5: =350+273.15 -> 623.15 | O5: =$K5+$L5*N5+$M5*N5^2 -> -1543.1406 | P5: =302+273.15 -> 575.15 | Q5: =$K5+$L5*P5+$M5*P5^2 -> -1543.3909
A6: MAC + 1.5O2 → Acrolein + CO2 + H2O | E6: =C23+C19+C29-C26 -> -607.652 | F6: =D23+D19+D29-D26 -> 0.01522613 | G6: =E23+E19+E29-E26 -> -1.27419e-05 | H6: acro | J6: =H7 -> acetal | K6: =E7 -> -1088.494 | L6: =F7 -> 0.02768826 | M6: =G7 -> -3.25734e-05 | N6: =350+273.15 -> 623.15 | O6: =$K6+$L6*N6+$M6*N6^2 -> -1083.8888 | P6: =302+273.15 -> 575.15 | Q6: =$K6+$L6*P6+$M6*P6^2 -> -1083.3443
A7: MAC + 2.5O2 → Acetaldehyde + 2CO2 + H2O | E7: =C22+2*C19+C29-C26 -> -1088.494 | F7: =D22+2*D19+D29-D26 -> 0.02768826 | G7: =E22+2*E19+E29-E26 -> -3.25734e-05 | H7: acetal | J7: =H8 -> co2 | K7: =E8+E10 -> -4729.49 | L7: =F8+F10 -> 0.08384504 | M7: =G8+G10 -> -8.12448e-05 | N7: =350+273.15 -> 623.15 | O7: =$K7+$L7*N7+$M7*N7^2 -> -4708.7906 | P7: =302+273.15 -> 575.15 | Q7: =$K7+$L7*P7+$M7*P7^2 -> -4708.1421
A8: IB + 4O2 → 4CO2 + 4 H2O | E8: =4*C19+4*C29-C31 -> -2531.454 | F8: =4*D19+4*D29-D31 -> 0.03320252 | G8: =4*E19+4*E29-E31 -> -3.11346e-05 | H8: co2 | J8: =H9 -> co | K8: =E9+E11 -> -3604.562 | L8: =F9+F11 -> 0.11571732 | M8: =G9+G11 -> -0.0001078368 | N8: =350+273.15 -> 623.15 | O8: =$K8+$L8*N8+$M8*N8^2 -> -3574.3275 | P8: =302+273.15 -> 575.15 | Q8: =$K8+$L8*P8+$M8*P8^2 -> -3573.6793
A9: IB + 2 O2 → 4CO + 4 H2O | E9: =4*C18+4*C29-C31 -> -1406.526 | F9: =4*D18+4*D29-D31 -> 0.0650748 | G9: =4*E18+4*E29-E31 -> -5.77266e-05 | H9: co | J9: =H12 -> mac | K9: =E12 -> -333.418 | L9: =F12 -> -0.01744 | M9: =G12 -> 1.89756e-05 | N9: =350+273.15 -> 623.15 | O9: =$K9+$L9*N9+$M9*N9^2 -> -336.91721 | P9: =302+273.15 -> 575.15 | Q9: =$K9+$L9*P9+$M9*P9^2 -> -337.17153
A10: MAC + 5.5O2 → 4CO2 + 3H2O | E10: =4*C19+3*C29-C26 -> -2198.036 | F10: =4*D19+3*D29-D26 -> 0.05064252 | G10: =4*E19+3*E29-E26 -> -5.01102e-05 | H10: co2 | J10: =H13 -> maa | K10: =E13 -> -339.158 | L10: =F13 -> 0.039334389 | M10: =G13 -> 0.00029454092 | N10: =350+273.15 -> 623.15 | O10: =$K10+$L10*N10+$M10*N10^2 -> -200.27185 | P10: =302+273.15 -> 575.15 | Q10: =$K10+$L10*P10+$M10*P10^2 -> -219.10142
A11: MAC + 3.5O2 → 4CO + 3H2O | E11: =4*C19+3*C29-C26 -> -2198.036 | F11: =4*D19+3*D29-D26 -> 0.05064252 | G11: =4*E19+3*E29-E26 -> -5.01102e-05 | H11: co | J11: formal | K11: =-(E14+E15) -> 763.09 | L11: =-(F14+F15) -> -0.03005833 | M11: =-(G14+G15) -> 1.96452e-05 | N11: =350+273.15 -> 623.15 | O11: =$K11+$L11*N11+$M11*N11^2 -> 751.9877 | P11: =302+273.15 -> 575.15 | Q11: =$K11+$L11*P11+$M11*P11^2 -> 752.30053
A12: IB + O2 → MAC + H2O | E12: =C26+C29-C31 -> -333.418 | F12: =D26+D29-D31 -> -0.01744 | G12: =E26+E29-E31 -> 1.89756e-05 | H12: mac
A13: MAC + 0.5 O2 → MAA | E13: =C27-C26 -> -339.158 | F13: =D27-D26 -> 0.039334389 | G13: =E27-E26 -> 0.00029454092 | H13: maa
A14: Formaldehyde + O2 → CO2 + H2O | E14: =C19+C29-C20 -> -522.161 | F14: =D19+D29-D20 -> 0.01104513 | G14: =E19+E29-E20 -> -6.4986e-06 | H14: form
A15: Formaldehyde + 0.5O2 → CO + H2O | E15: =C18+C29-C20 -> -240.929 | F15: =D18+D29-D20 -> 0.0190132 | G15: =E18+E29-E20 -> -1.31466e-05 | H15: form
B17: component | C17: A | D17: B | E17: C | F17: At 25 deg c | G17: 298 | H17: =N2 -> 623.15 | N17: MAC formation | Q17: Reaction no. | R17: Gibbs energy (kJ/mol) | S17: ΔH_rxn (kJ/mol)
B18: CO | C18: -112.19 | D18: 0.0081182 | E18: -8.0425e-06 | G18: =$G$17*C18+$G$17^2*D18/2+$G$17^3*E18/3 -> -33143.1 | K18: IB + O2 → Acetone + Formaldehyde | N18: A | O18: B | P18: C | Q18: 1 | R18: -344.31 | S18: =O9 -> -336.91721
B19: CO2 | C19: -393.422 | D19: 0.00015013 | E19: -1.3945e-06 | G19: =$G$17*C19+$G$17^2*D19/2+$G$17^3*E19/3 -> -117245.39 | K19: MAC +3O2 → Acetic acid + CO2 + H2O | N19: =C26+C29-C31 -> -333.418 | O19: =D26+D29-D31 -> -0.01744 | P19: =E26+E29-E31 -> 1.89756e-05 | Q19: 2 | R19: -230.12 | S19: =O10 -> -200.27185
B20: Formaldehyde | C20: -109.671 | D20: -0.023151 | E20: 7.8697e-06 | G20: =$G$17*C20+$G$17^2*D20/2+$G$17^3*E20/3 -> -33640.489 | K20: MAC + 2O2 → Acryclic acid + H2O | Q20: 3 | R20: -75.06 | S20: -112.2
B21: acetic acid | C21: -422.584 | D21: -4.8354 | E21: 2.337e-05 | G21: =$G$17*C21+$G$17^2*D21/2+$G$17^3*E21/3 -> -340425.31 | K21: IB + 2.5 O2 → Acroelin + CO2 + 2H2O | N21: MAA formation
B22: Acetaldehyde | C22: -154.122 | D22: -0.047166 | E22: 2.0279e-05 | G22: =$G$17*C22+$G$17^2*D22/2+$G$17^3*E22/3 -> -47843.736 | K22: MAC + 1.5O2 → Acrolein + CO2 + H2O | N22: =F27-F26 -> -255.88005
B23: Acrolein | C23: -66.702 | D23: -0.059478 | E23: 3.8716e-05 | G23: =$G$17*C23+$G$17^2*D23/2+$G$17^3*E23/3 -> -22176.617 | K23: MAC + 2.5O2 → Acetaldehyde + 2CO2 + H2O
B24: Acryclic acid | C24: -325.038 | D24: -0.044058 | E24: 2.0926e-05 | G24: =$G$17*C24+$G$17^2*D24/2+$G$17^3*E24/3 -> -98632.995 | K24: IB + 4O2 → 4CO2 + 4 H2O
B25: Acetone | C25: -199.175 | D25: -0.071484 | E25: 3.2534e-05 | G25: =$G$17*C25+$G$17^2*D25/2+$G$17^3*E25/3 -> -62241.194 | K25: IB + 2 O2 → 4CO + 4 H2O
B26: Methacrolein | C26: -90.882 | D26: -0.08681 | E26: 5.2829e-05 | F26: =C26+D26*298+E26*298^2 -> -112.05995 | G26: =$G$17*C26+$G$17^2*D26/2+$G$17^3*E26/3 -> -30471.359 | K26: MAC + 5.5O2 → 4CO2 + 3H2O
B27: Methacrylic acid | C27: =-430.04 -> -430.04 | D27: -0.047475611 | E27: 0.00034736992 | F27: =-367.94 -> -367.94 | G27: =$G$17*C27+$G$17^2*D27/2+$G$17^3*E27/3 -> -127195.71 | K27: MAC + 3.5O2 → 4CO + 3H2O
B28: Impurity (TPA) | C28: -688.693 | D28: -0.11323 | E28: 4.9298e-05 | G28: =$G$17*C28+$G$17^2*D28/2+$G$17^3*E28/3 -> -209823.29 | K28: IB + O2 → MAC + H2O
B29: Water | C29: -238.41 | D29: -0.012256 | E29: 2.7656e-06 | G29: =$G$17*C29+$G$17^2*D29/2+$G$17^3*E29/3 -> -71565.975 | K29: MAC + 0.5 O2 → MAA
B30: Ethylene Oxide | C30: -38.88 | D30: -0.054041 | E30: 2.5601e-05 | G30: =$G$17*C30+$G$17^2*D30/2+$G$17^3*E30/3 -> -13759.937 | K30: Formaldehyde + O2 → CO2 + H2O
B31: Isobutylene | C31: 4.126 | D31: -0.081626 | E31: =0.000036619 -> 3.6619e-05 | G31: =$G$17*C31+$G$17^2*D31/2+$G$17^3*E31/3 -> -2071.7862 | H31: =C31+D31*H17+E31*H17^2 -> -32.519501 | K31: Formaldehyde + 0.5O2 → CO + H2O

Sheet r1
G1: C4H8 + O2 → C4H6O + H2O | K1: 4.8% by volume of methacrolein, 0.74 mol% of CO, 0.21 mol% of methacrylic acid, 0.21 mol% of acetic acid, 0.12 mol% of acetone, 0.21 mol% of acetaldehyde, 0.04 mol% of acrolein, 0.03 mol% of formaldehyde, 0.03 mol% of acrylic acid, 250ppm of isobutylene and 3.5% by volume of oxyge
W4: using elemental balance | AA4: kmol/h
L5: ='stream compositions'!C21 -> mol% | M5: ='stream compositions'!D21 -> kmol/h | N5: ='stream compositions'!E21 -> mw | O5: ='stream compositions'!F21 -> kg/h | P5: wt% | R5: o2 consumed | S5: =D8-M16 -> 57.15 | T5: kmol/h | W5: In | X5: Out | Y5: diff | AA5: =N5 -> mw | AB5: =O5 -> kg/h | AC5: =P5 -> wt% | AD5: =Q5 -> 0
C6: ='stream compositions'!C14 -> mol% | D6: ='stream compositions'!D14 -> kmol/h | E6: ='stream compositions'!E14 -> mw | F6: ='stream compositions'!F14 -> kg/h | G6: kg/day | K6: ='stream compositions'!B22 -> IB | L6: =M6/$M$21% -> 0.03415368 | M6: =D7*(1-I14) -> 0.167 | N6: 56 | O6: =250/1000000*O21 -> 3.6066307 | P6: =O6/O21*100 -> 0.025 | R6: ib consumed | S6: =D7-M6 -> 41.583 | T6: kmol/h | V6: C | W6: =4*D7 -> 167 | X6: =AA21 -> 12059.068 | Y6: =W6-X6 -> -11892.068 | Z6: CO2 | AA6: =N6*$M6 -> 9.352 | AB6: =O6*$M6 -> 0.60230732 | AC6: =P6*$M6 -> 0.004175 | AD6: =Q6*$M6 -> 0
B7: ='stream compositions'!B15 -> IB | C7: ='stream compositions'!C15 -> 8.627451 | D7: ='stream compositions'!D15 -> 41.75 | E7: ='stream compositions'!E15 -> 56 | F7: ='stream compositions'!F15 -> 2338 | G7: =F7*24 -> 56112 | K7: ='stream compositions'!B23 -> MAC | L7: =M7/$M$21% -> 7.0488496 | M7: =D7*I16 -> 34.466502 | N7: 70 | O7: =M7*N7 -> 2412.6551 | P7: =O7/$O$21% -> 16.723747 | R7: o2/ib | S7: =S5/S6 -> 1.3743597 | V7: H | W7: =8*D7+2*D10 -> 459.25 | X7: =AB21 -> 2560561.6 | Y7: =W7-X7 -> -2560102.3 | Z7: H2O | AA7: =N7*$M7 -> 2412.6551 | AB7: =O7*$M7 -> 83155.784 | AC7: =P7*$M7 -> 576.40906 | AD7: =Q7*$M7 -> 0
B8: ='stream compositions'!B16 -> O2 | C8: ='stream compositions'!C16 -> 17.254902 | D8: ='stream compositions'!D16 -> 83.5 | E8: ='stream compositions'!E16 -> 32 | F8: ='stream compositions'!F16 -> 2672 | G8: =F8*24 -> 64128 | K8: ='stream compositions'!B24 -> CO | L8: =M8/$M$21% -> 1.0478064 | M8: 5.1234208 | N8: 28 | O8: =M8*N8 -> 143.45578 | P8: =O8/$O$21% -> 0.9943892 | V8: O | W8: =2*D8+D10 -> 229.625 | X8: =AC21 -> 17748.987 | Y8: =W8-X8 -> -17519.362 | Z8: =Y7/2 -> -1280051.2 | AA8: =N8*$M8 -> 143.45578 | AB8: =O8*$M8 -> 734.98435 | AC8: =P8*$M8 -> 5.0946743 | AD8: =Q8*$M8 -> 0
B9: ='stream compositions'!B17 -> N2 | C9: ='stream compositions'!C17 -> 61.176471 | D9: ='stream compositions'!D17 -> 296.04545 | E9: ='stream compositions'!E17 -> 28 | F9: ='stream compositions'!F17 -> 8289.2727 | G9: =F9*24 -> 198942.55 | K9: ='stream compositions'!B25 -> MAA | L9: =M9/$M$21% -> 0.29735048 | M9: 1.4539438 | N9: 86 | O9: =M9*N9 -> 125.03916 | P9: =O9/$O$21% -> 0.86673112 | S9: =O21/M21 -> 29.504122 | V9: N | W9: =2*D9 -> 592.09091 | X9: =AD21 -> 1.4781411 | Y9: =W9-X9 -> 590.61277 | AA9: =N9*$M9 -> 125.03916 | AB9: =O9*$M9 -> 181.79991 | AC9: =P9*$M9 -> 1.2601783 | AD9: =Q9*$M9 -> 0
B10: ='stream compositions'!B18 -> steam | C10: ='stream compositions'!C18 -> 12.941176 | D10: ='stream compositions'!D18 -> 62.625 | E10: ='stream compositions'!E18 -> 18 | F10: ='stream compositions'!F18 -> 1127.25 | G10: =F10*24 -> 27054 | K10: ='stream compositions'!B26 -> Acetic ac | L10: =M10/$M$21% -> 0.29735048 | M10: 1.4539438 | N10: 60 | O10: =M10*N10 -> 87.236625 | P10: =O10/$O$21% -> 0.60469613 | AA10: =N10*$M10 -> 87.236625 | AB10: =O10*$M10 -> 126.83715 | AC10: =P10*$M10 -> 0.87919416 | AD10: =Q10*$M10 -> 0
B11: Total | C11: ='stream compositions'!C19 -> 0 | D11: =SUM(D7:D10) -> 483.92045 | F11: ='stream compositions'!F19 -> 14426.523 | K11: ='stream compositions'!B27 -> acetone | L11: =M11/$M$21% -> 0.16991456 | M11: 0.830825 | N11: 58 | O11: =M11*N11 -> 48.18785 | P11: =O11/$O$21% -> 0.33402263 | AA11: =N11*$M11 -> 48.18785 | AB11: =O11*$M11 -> 40.03567 | AC11: =P11*$M11 -> 0.27751435 | AD11: =Q11*$M11 -> 0
D12: =D11*1000/3600 -> 134.42235 | E12: mol/s | G12: =SUM(G8:G9) -> 263070.55 | K12: ='stream compositions'!B28 -> acetalde | L12: =M12/$M$21% -> 0.29735048 | M12: 1.4539438 | N12: 44 | O12: =M12*N12 -> 63.973525 | P12: =O12/$O$21% -> 0.44344383 | AA12: =N12*$M12 -> 63.973525 | AB12: =O12*$M12 -> 93.013907 | AC12: =P12*$M12 -> 0.64474239 | AD12: =Q12*$M12 -> 0
K13: ='stream compositions'!B29 -> acrolein | L13: =M13/$M$21% -> 0.056638186 | M13: 0.27694167 | N13: 56 | O13: =M13*N13 -> 15.508733 | P13: =O13/$O$21% -> 0.10750153 | AA13: =N13*$M13 -> 15.508733 | AB13: =O13*$M13 -> 4.2950145 | AC13: =P13*$M13 -> 0.029771654 | AD13: =Q13*$M13 -> 0
H14: conv | I14: 0.996 | K14: ='stream compositions'!B30 -> formaldehyde | L14: =M14/$M$21% -> 0.042478639 | M14: 0.20770625 | N14: 30 | O14: =M14*N14 -> 6.2311875 | P14: =O14/$O$21% -> 0.043192581 | Q14: =D7*I14*(1-I15) -> 7.1164979 | AA14: =N14*$M14 -> 6.2311875 | AB14: =O14*$M14 -> 1.2942566 | AC14: =P14*$M14 -> 0.008971369 | AD14: =Q14*$M14 -> 1.4781411
H15: selectivity | I15: =I16/I14 -> 0.8288604 | K15: ='stream compositions'!B31 -> acrylic acid | L15: =M15/$M$21% -> 0.042478639 | M15: 0.20770625 | N15: 72 | O15: =M15*N15 -> 14.95485 | P15: =O15/$O$21% -> 0.10366219 | AA15: =N15*$M15 -> 14.95485 | AB15: =O15*$M15 -> 3.1062158 | AC15: =P15*$M15 -> 0.021531286 | AD15: =Q15*$M15 -> 0
H16: yield | I16: 0.82554496 | K16: O2 | L16: =M16/$M$21% -> 5.388919 | M16: 26.35 | N16: 32 | O16: =M16*N16 -> 843.2 | P16: =O16/$O$21% -> 5.8447903 | AA16: =N16*$M16 -> 843.2 | AB16: =O16*$M16 -> 22218.32 | AC16: =P16*$M16 -> 154.01022 | AD16: =Q16*$M16 -> 0
K17: N2 | L17: =M17/$M$21% -> 60.54516 | M17: =D9 -> 296.04545 | N17: 28 | O17: =M17*N17 -> 8289.2727 | P17: =O17/$O$21% -> 57.458564 | AA17: =N17*$M17 -> 8289.2727 | AB17: =O17*$M17 -> 2454001.5 | AC17: =P17*$M17 -> 17010.347 | AD17: =Q17*$M17 -> 0
K18: ='stream compositions'!B34 -> CO2 | L18: =M18/$M$21% -> 1.5454839 | M18: ='elemental balance for r1'!H34 -> 7.5568959 | N18: 44 | O18: =M18*N18 -> 332.50342 | P18: =O18/$O$21% -> 2.3048064
K19: ='stream compositions'!B35 -> steam | L19: =M19/$M$21% -> 23.186066 | M19: ='elemental balance for r1'!I35 -> 113.37206 | N19: 18 | O19: =M19*N19 -> 2040.6971 | P19: =O19/$O$21% -> 14.145454 | Q19: =M19-D10 -> 50.74706
K20: formic acid | L20: =M20/$M$21% -> 0 | M20: ='elemental balance for r1'!G45 -> 0 | N20: 46 | O20: =M20*N20 -> 0 | P20: =O20/$O$21% -> 0 | Q20: =SUM(M8:M15,M18)+Q19 -> 69.312388
K21: ='stream compositions'!B36 -> total | L21: =SUM(L6:L20) -> 100 | M21: =SUM(M6:M20) -> 488.96634 | O21: =F11 -> 14426.523 | P21: =O21/$O$21% -> 100 | AA21: =SUM(AA6:AA19) -> 12059.068 | AB21: =SUM(AB6:AB19) -> 2560561.6 | AC21: =SUM(AC6:AC19) -> 17748.987 | AD21: =SUM(AD6:AD19) -> 1.4781411
O22: =SUM(O6:O20) -> 14426.523
B25: gas phase | D25: Regression coefficients for enthalpy of formation | P25: regression coefficients | AB25: Hrxn per moleproduct (kJ/mol)
A26: PG1 | B26: =D6 -> kmol/h | C26: mol/h | D26: T | E26: A | F26: B | G26: C | H26: H (kJ/mol) | I26: H (kJ/h) | L26: PG2 | M26: =M5 -> kmol/h | N26: mol/h | O26: T | P26: A | Q26: B | R26: C | S26: H (kJ/mol) | T26: H (kJ/h) | V26: Reactions | Y26: A | Z26: B | AA26: C | AB26: 298 | AC26: 623.15 | AD26: product flow rate | AE26: Hrx (kJ/h) | AF26: extent | AG26: Hrx*extent | AL26: reg coefficients for Cp (J/molK)
A27: =B7 -> IB | B27: =D7 -> 41.75 | C27: =B27*1000 -> 41750 | D27: =350+273.15 -> 623.15 | E27: ='heat of reactions'!C31 -> 4.126 | F27: ='heat of reactions'!D31 -> -0.081626 | G27: ='heat of reactions'!E31 -> 3.6619e-05 | H27: =P27+Q27*O27+R27*O27^2 -> -32.519501 | I27: =H27*C27 -> -1357689.2 | L27: IB | M27: =M6 -> 0.167 | N27: =M27*1000 -> 167 | O27: =350+273.15 -> 623.15 | P27: ='heat of reactions'!C31 -> 4.126 | Q27: ='heat of reactions'!D31 -> -0.081626 | R27: ='heat of reactions'!E31 -> 3.6619e-05 | S27: =P27+Q27*O27+R27*O27^2 -> -32.519501 | T27: =S27*N27 -> -5430.7567 | V27: IB + O2 → MAC + H2O | Y27: -333.418 | Z27: -0.01744 | AA27: 1.89756e-05 | AB27: -336.93001 | AC27: -336.91721 | AD27: =N28 -> 34466.502 | AE27: =AD27*AC27 -> -11612358 | AF27: 38.7264 | AG27: =AF27*AC27 -> -13047.591 | AJ27: component | AK27: Tb | AL27: A | AM27: B | AN27: C | AO27: D | AP27: E | AQ27: T_ref | AR27: T_rxn | AS27: Cp | AT27: flow rate (mol/h) | AU27: Fcp
A28: =B8 -> O2 | B28: =D8 -> 83.5 | C28: =B28*1000 -> 83500 | D28: =350+273.15 -> 623.15 | E28: 0 | F28: 0 | G28: 0 | H28: =E28+F28*D28*G28*D28^2 -> 0 | I28: =H28*C28 -> 0 | L28: MAC | M28: =M7 -> 34.466502 | N28: =M28*1000 -> 34466.502 | O28: =350+273.15 -> 623.15 | P28: ='heat of reactions'!C26 -> -90.882 | Q28: ='heat of reactions'!D26 -> -0.08681 | R28: ='heat of reactions'!E26 -> 5.2829e-05 | S28: =P28+Q28*O28+R28*O28^2 -> -124.46331 | T28: =S28*N28 -> -4289814.9 | V28: IB + 1.5 O2 → MAA + H2O | Y28: -339.158 | Z28: 0.039334389 | AA28: 0.00029454092 | AB28: -301.27994 | AC28: -200.27185 | AD28: =N30 -> 1453.9437 | AE28: =AD28*AC28 -> -291184 | AF28: 1.5191 | AG28: =AF28*AC28 -> -304.23296 | AJ28: CO | AL28: =29.556 -> 29.556 | AM28: =-0.0065807 -> -0.0065807 | AN28: 2.013e-05 | AO28: -1.2227e-08 | AP28: 2.6717e-12 | AQ28: 500 | AR28: =O27 -> 623.15 | AS28: =AL28+AM28*AR28+AN28*AR28^2+AO28*AR28^3+AP28*AR28^4 -> 30.716222 | AT28: =N29 -> 5123.4208 | AU28: =AT28*AS28 -> 157372.13
A29: =B9 -> N2 | B29: =D9 -> 296.04545 | C29: =B29*1000 -> 296045.45 | D29: =350+273.15 -> 623.15 | E29: 0 | F29: 0 | G29: 0 | H29: =E29+F29*D29*G29*D29^2 -> 0 | I29: =H29*C29 -> 0 | L29: CO | M29: =M8 -> 5.1234208 | N29: =M29*1000 -> 5123.4208 | O29: =350+273.15 -> 623.15 | P29: ='heat of reactions'!C18 -> -112.19 | Q29: ='heat of reactions'!D18 -> 0.0081182 | R29: ='heat of reactions'!E18 -> -8.0425e-06 | S29: =P29+Q29*O29+R29*O29^2 -> -110.25417 | T29: =S29*N29 -> -564878.53 | V29: IB +5O2 → Acetic acid + CO2 + 3H2O | Y29: -1535.362 | Z29: -4.7903919 | AA29: -6.3467e-06 | AB29: -2963.4624 | AC29: -4522.9592 | AD29: =N31 -> 1453.9437 | AE29: =AD29*AC29 -> -6576128.3 | AF29: 1.1094 | AG29: =AF29*AC29 -> -5017.771 | AJ29: CO2 | AL29: 27.437 | AM29: 0.042315 | AN29: =-0.000019555 -> -1.9555e-05 | AO29: =0.0000000039968 -> 3.9968e-09 | AP29: =-0.00000000000029872 -> -2.9872e-13 | AQ29: 500 | AR29: =O28 -> 623.15 | AS29: =AL29+AM29*AR29+AN29*AR29^2+AO29*AR29^3+AP29*AR29^4 -> 47.134173 | AT29: =N39 -> 7556.8959 | AU29: =AT29*AS29 -> 356188.04
A30: =B10 -> steam | B30: =D10 -> 62.625 | C30: =B30*1000 -> 62625 | D30: =350+273.15 -> 623.15 | E30: ='heat of reactions'!C29 -> -238.41 | F30: ='heat of reactions'!D29 -> -0.012256 | G30: ='heat of reactions'!E29 -> 2.7656e-06 | H30: =E30+F30*D30*G30*D30^2 -> -246.61193 | I30: =H30*C30 -> -15444072 | L30: MAA | M30: =M9 -> 1.4539438 | N30: =M30*1000 -> 1453.9437 | O30: =350+273.15 -> 623.15 | P30: ='heat of reactions'!C27 -> -430.04 | Q30: ='heat of reactions'!D27 -> -0.047475611 | R30: ='heat of reactions'!E27 -> 0.00034736992 | S30: =P30+Q30*O30+R30*O30^2 -> -324.73516 | T30: =S30*N30 -> -472146.65 | V30: IB + 3O2 → Acryclic acid + 2H2O | Y30: -805.984 | Z30: 0.013056 | AA30: -1.01618e-05 | AB30: -802.99572 | AC30: -801.79414 | AD30: =N36 -> 207.70625 | AE30: =AD30*AC30 -> -166537.65 | AF30: 0.3032 | AG30: =AF30*AC30 -> -243.10398 | AJ30: formaldehyde | AK30: 254.05 | AL30: =34.428 -> 34.428 | AM30: =-0.029779 -> -0.029779 | AN30: =0.00015104 -> 0.00015104 | AO30: =-0.00000012733 -> -1.2733e-07 | AP30: =0.000000000033887 -> 3.3887e-11 | AQ30: 500 | AR30: =O29 -> 623.15 | AS30: =AL30+AM30*AR30+AN30*AR30^2+AO30*AR30^3+AP30*AR30^4 -> 48.821054 | AT30: =N35 -> 207.70625 | AU30: =AT30*AS30 -> 10140.438
A31: =B11 -> Total | B31: =D11 -> 483.92045 | C31: =SUM(C27:C30) -> 483920.45 | D31: =350+273.15 -> 623.15 | I31: =SUM(I27:I30) -> -16801761 | L31: Acetic ac | M31: =M10 -> 1.4539438 | N31: =M31*1000 -> 1453.9437 | O31: =350+273.15 -> 623.15 | P31: ='heat of reactions'!C21 -> -422.584 | Q31: ='heat of reactions'!D21 -> -4.8354 | R31: ='heat of reactions'!E21 -> 2.337e-05 | S31: =P31+Q31*O31+R31*O31^2 -> -3426.6886 | T31: =S31*N31 -> -4982212.4 | V31: IB + 2.5O2 → Acrolein + CO2 +2 H2O | Y31: 0 | Z31: 0 | AA31: 0 | AB31: 0 | AC31: 0 | AD31: 0 | AE31: =AD31*AC31 -> 0 | AF31: 0 | AG31: =AF31*AC31 -> 0 | AJ31: acetic acid | AK31: =AW28 -> 0 | AL31: =34.85 -> 34.85 | AM31: =0.037626 -> 0.037626 | AN31: 0.00028311 | AO31: =-0.00000030767 -> -3.0767e-07 | AP31: 9.2646e-11 | AQ31: 500 | AR31: =O30 -> 623.15 | AS31: =AL31+AM31*AR31+AN31*AR31^2+AO31*AR31^3+AP31*AR31^4 -> 107.75308 | AT31: =N31 -> 1453.9437 | AU31: =AT31*AS31 -> 156666.92
L32: acetone | M32: =M11 -> 0.830825 | N32: =M32*1000 -> 830.825 | O32: =350+273.15 -> 623.15 | P32: ='heat of reactions'!C25 -> -199.175 | Q32: ='heat of reactions'!D25 -> -0.071484 | R32: ='heat of reactions'!E25 -> 3.2534e-05 | S32: =P32+Q32*O32+R32*O32^2 -> -231.08678 | T32: =S32*N32 -> -191992.68 | V32: IB + 3O2 → Acetaldehyde + 2CO + 2H2O | Y32: -859.448 | Z32: 0.0261844 | AA32: -2.68938e-05 | AB32: -854.03333 | AC32: -853.57448 | AD32: =N33 -> 1453.9437 | AE32: =AD32*AC32 -> -1241049.3 | AF32: 1.1094 | AG32: =AF32*AC32 -> -946.95553 | AJ32: acetaldehyde | AK32: 293.55 | AL32: =34.14 -> 34.14 | AM32: 0.04002 | AN32: =0.00015634 -> 0.00015634 | AO32: =-0.00000016445 -> -1.6445e-07 | AP32: =0.000000000047248 -> 4.7248e-11 | AQ32: 500 | AR32: =O31 -> 623.15 | AS32: =AL32+AM32*AR32+AN32*AR32^2+AO32*AR32^3+AP32*AR32^4 -> 87.118807 | AT32: =N33 -> 1453.9437 | AU32: =AT32*AS32 -> 126665.85
L33: acetaldehyde | M33: =M12 -> 1.4539438 | N33: =M33*1000 -> 1453.9437 | O33: =350+273.15 -> 623.15 | P33: ='heat of reactions'!C22 -> -154.122 | Q33: ='heat of reactions'!D22 -> -0.047166 | R33: ='heat of reactions'!E22 -> 2.0279e-05 | S33: =P33+Q33*O33+R33*O33^2 -> -175.63883 | T33: =S33*N33 -> -255368.99 | V33: IB + 6O2 → 4CO2 + 4 H2O | Y33: -2531.454 | Z33: 0.03320252 | AA33: -3.11346e-05 | AB33: -2524.3245 | AC33: -2522.8539 | AD33: =M39 -> 7.5568959 | AE33: =AD33*AC33 -> -19064.944 | AF33: 1.165 | AG33: =AF33*AC33 -> -2939.1248 | AJ33: acrolein | AK33: 325.84 | AL33: =109.243 -> 109.243 | AM33: =-0.50952 -> -0.50952 | AN33: =0.0017059 -> 0.0017059 | AO33: =-0.0000018068 -> -1.8068e-06 | AP33: =0.00000000065983 -> 6.5983e-10 | AQ33: 500 | AR33: =O32 -> 623.15 | AS33: =AL33+AM33*AR33+AN33*AR33^2+AO33*AR33^3+AP33*AR33^4 -> 116.45124 | AT33: =N34 -> 276.94167 | AU33: =AT33*AS33 -> 32250.201
L34: acrolein | M34: =M13 -> 0.27694167 | N34: =M34*1000 -> 276.94167 | O34: =350+273.15 -> 623.15 | P34: ='heat of reactions'!C23 -> -66.702 | Q34: ='heat of reactions'!D23 -> -0.059478 | R34: ='heat of reactions'!E23 -> 3.8716e-05 | S34: =P34+Q34*O34+R34*O34^2 -> -88.731676 | T34: =S34*N34 -> -24573.498 | V34: IB + 4O2 → 4CO + 4 H2O | Y34: -1406.526 | Z34: 0.0650748 | AA34: -5.77266e-05 | AB34: -1392.2601 | AC34: -1388.3908 | AD34: =M29 -> 5.1234208 | AE34: =AD34*AC34 -> -7113.3103 | AF34: 0.6542 | AG34: =AF34*AC34 -> -908.28526 | AJ34: acryclic acid | AK34: =AW29 -> 0 | AL34: =7.755 -> 7.755 | AM34: =0.29386 -> 0.29386 | AN34: =-0.00020878 -> -0.00020878 | AO34: =0.000000071591 -> 7.1591e-08 | AP34: =-0.000000000009096 -> -9.096e-12 | AQ34: 500 | AR34: =O33 -> 623.15 | AS34: =AL34+AM34*AR34+AN34*AR34^2+AO34*AR34^3+AP34*AR34^4 -> 125.75321 | AT34: =N36 -> 207.70625 | AU34: =AT34*AS34 -> 26119.727
L35: formaldehyde | M35: =M14 -> 0.20770625 | N35: =M35*1000 -> 207.70625 | O35: =350+273.15 -> 623.15 | P35: ='heat of reactions'!C20 -> -109.671 | Q35: ='heat of reactions'!D20 -> -0.023151 | R35: ='heat of reactions'!E20 -> 7.8697e-06 | S35: =P35+Q35*O35+R35*O35^2 -> -121.04162 | T35: =S35*N35 -> -25141.1 | V35: IB + 2.5 O2 → Acroelin + CO2 + 2H2O | Y35: -941.07 | Z35: -0.00221387 | AA35: 6.2337e-06 | AB35: -941.17616 | AC35: -940.02893 | AD35: =N34 -> 276.94167 | AE35: =AD35*AC35 -> -260333.18 | AF35: 0.5194 | AG35: =AF35*AC35 -> -488.25103 | AJ35: acetone | AK35: 329.44 | AL35: =35.918 -> 35.918 | AM35: =0.093896 -> 0.093896 | AN35: =0.0001873 -> 0.0001873 | AO35: =-0.00000021643 -> -2.1643e-07 | AP35: =0.000000000063174 -> 6.3174e-11 | AQ35: 500 | AR35: =O34 -> 623.15 | AS35: =AL35+AM35*AR35+AN35*AR35^2+AO35*AR35^3+AP35*AR35^4 -> 124.3153 | AT35: =N32 -> 830.825 | AU35: =AT35*AS35 -> 103284.26
L36: acrylic acid | M36: =M15 -> 0.20770625 | N36: =M36*1000 -> 207.70625 | O36: =350+273.15 -> 623.15 | P36: ='heat of reactions'!C24 -> -325.038 | Q36: ='heat of reactions'!D24 -> -0.044058 | R36: ='heat of reactions'!E24 -> 2.0926e-05 | S36: =P36+Q36*O36+R36*O36^2 -> -344.36684 | T36: =S36*N36 -> -71527.146 | V36: MAC + 5O2 → 4CO2 + 3H2O | Y36: 0 | Z36: 0 | AA36: 0 | AB36: 0 | AC36: 0 | AD36: 0 | AE36: =AD36*AC36 -> 0 | AF36: 0 | AG36: =AF36*AC36 -> 0 | AJ36: methacrolein | AK36: =AW30 -> 0 | AL36: =14.506 -> 14.506 | AM36: =0.15922 -> 0.15922 | AN36: =0.0003118 -> 0.0003118 | AO36: =-0.000000421 -> -4.21e-07 | AP36: =0.00000000014222 -> 1.4222e-10 | AQ36: 500 | AR36: =O35 -> 623.15 | AS36: =AL36+AM36*AR36+AN36*AR36^2+AO36*AR36^3+AP36*AR36^4 -> 154.37291 | AT36: =N28 -> 34466.502 | AU36: =AT36*AS36 -> 5320694.2
L37: O2 | M37: =M16 -> 26.35 | N37: =M37*1000 -> 26350 | O37: =350+273.15 -> 623.15 | P37: 0 | Q37: 0 | R37: 0 | S37: =P37+Q37*O37+R37*O37^2 -> 0 | T37: =S37*N37 -> 0 | V37: MAC + 3O2 → 4CO + 3H2O | Y37: 0 | Z37: 0 | AA37: 0 | AB37: 0 | AC37: 0 | AD37: 0 | AE37: =AD37*AC37 -> 0 | AF37: 0 | AG37: =AF37*AC37 -> 0 | AJ37: methacrylic acid | AK37: =435 -> 435 | AL37: =-28.131 -> -28.131 | AM37: =0.54744 -> 0.54744 | AN37: =-0.00053877 -> -0.00053877 | AO37: 2.8583e-07 | AP37: =-0.000000000060864 -> -6.0864e-11 | AQ37: 500 | AR37: =O36 -> 623.15 | AS37: =AL37+AM37*AR37+AN37*AR37^2+AO37*AR37^3+AP37*AR37^4 -> 163.78051 | AT37: =N30 -> 1453.9437 | AU37: =AT37*AS37 -> 238127.64
L38: N2 | M38: =M17 -> 296.04545 | N38: =M38*1000 -> 296045.45 | O38: =350+273.15 -> 623.15 | P38: 0 | Q38: 0 | R38: 0 | S38: =P38+Q38*O38+R38*O38^2 -> 0 | T38: =S38*N38 -> 0 | V38: IB + O2 → Acetone + Formaldehyde | Y38: -312.972 | Z38: -0.013009 | AA38: 3.7847e-06 | AB38: -316.51259 | AC38: -319.6089 | AD38: =N32 -> 830.825 | AE38: =AD38*AC38 -> -265539.06 | AF38: 0.6115 | AG38: =AF38*AC38 -> -195.44084 | AJ38: water | AK38: 373.15 | AL38: 33.933 | AM38: -0.0084186 | AN38: 2.9906e-05 | AO38: -1.7825e-08 | AP38: 3.6934e-12 | AQ38: 500 | AR38: =O38 -> 623.15 | AS38: =AL38+AM38*AR38+AN38*AR38^2+AO38*AR38^3+AP38*AR38^4 -> 36.543574 | AT38: =N40 -> 113372.06 | AU38: =AT38*AS38 -> 4143020.2
L39: CO2 | M39: =M18 -> 7.5568959 | N39: =M39*1000 -> 7556.8959 | O39: =350+273.15 -> 623.15 | P39: ='heat of reactions'!C19 -> -393.422 | Q39: ='heat of reactions'!D19 -> 0.00015013 | R39: ='heat of reactions'!E19 -> -1.3945e-06 | S39: =P39+Q39*O39+R39*O39^2 -> -393.86995 | T39: =S39*N39 -> -2976434.2 | V39: Formaldehyde + 0.5O2 → co | Y39: 0 | Z39: 0 | AA39: 0 | AB39: 0 | AC39: 0 | AD39: 0 | AE39: =AD39*AC39 -> 0 | AF39: 0.5718 | AG39: =AF39*AC39 -> 0 | AJ39: Isobutylene | AL39: =32.918 -> 32.918 | AM39: =0.18546 -> 0.18546 | AN39: =0.000077876 -> 7.7876e-05 | AO39: =-0.00000014654 -> -1.4654e-07 | AP39: =0.000000000046867 -> 4.6867e-11 | AQ39: 500 | AR39: =O40 -> 623.15 | AS39: =AL39+AM39*AR39+AN39*AR39^2+AO39*AR39^3+AP39*AR39^4 -> 150.33532 | AT39: =N27 -> 167 | AU39: =AT39*AS39 -> 25105.998
L40: steam | M40: =M19 -> 113.37206 | N40: =M40*1000 -> 113372.06 | O40: =350+273.15 -> 623.15 | P40: ='heat of reactions'!C29 -> -238.41 | Q40: ='heat of reactions'!D29 -> -0.012256 | R40: ='heat of reactions'!E29 -> 2.7656e-06 | S40: =P40+Q40*O40+R40*O40^2 -> -244.9734 | T40: =S40*N40 -> -27773139 | V40: Formaldehyde + O2 → CO2 + H2O | Y40: -522.161 | Z40: 0.01104513 | AA40: -6.4986e-06 | AB40: -519.44665 | AC40: -517.80174 | AD40: =N35 -> 207.70625 | AE40: =AD40*AC40 -> -107550.66 | AF40: 0 | AG40: =AF40*AC40 -> 0 | AJ40: N2 | AL40: 29.342 | AM40: -0.035395 | AN40: 1.0076e-05 | AO40: -4.3116e-09 | AP40: 2.6e-13 | AQ40: 500 | AR40: =623.15 -> 623.15 | AS40: =AL40 -> 29.342 | AT40: =N38 -> 296045.45 | AU40: =AT40*AS40 -> 8686565.7
L41: total | M41: =M21 -> 488.96634 | N41: =SUM(N27:N40) -> 488966.34 | T41: =SUM(T27:T40) -> -41632660 | AC41: =SUM(AC27:AC40) -> -12404.201 | AE41: =SUM(AE27:AE40) -> -20546858 | AG41: =SUM(AG27:AG40) -> -24090.756 | AJ41: O2 | AL41: 29.526 | AM41: -0.0089 | AN41: 3.81e-05 | AO41: -3.2e-08 | AP41: 8.9e-12 | AQ41: =AQ40 -> 500 | AR41: =AR40 -> 623.15 | AS41: =AL41+AM41*AR41+AN41*AR41^2+AO41*AR41^3+AP41*AR41^4 -> 32.373496 | AT41: =N37 -> 26350 | AU41: =AT41*AS41 -> 853041.62
M42: =SUM(M27:M40) -> 488.96634 | N42: =M42*1000 -> 488966.34 | AT42: =SUM(AT28:AT41) -> 488966.34 | AU42: =SUM(AU28:AU41) -> 20235243
AC43: Hrxn*mol ib | AD43: =AC41*1000*N27 -> -2.0715016e+09
M44: Overall Energy Balance | AC44: T_rise | AD44: =AD43/AU42 -> -102.37098 | AE44: K
...

Sheet elemental balance for r1
B1: flow | D1: number of atoms | H1: elemental flow (kmol/h)
B2: kmol/h | C2: formula | D2: C | E2: H | F2: O | G2: N | H2: C | I2: H | J2: O | K2: N
A3: IB | B3: =r1!D7 -> 41.75 | C3: c4h8 | D3: 4 | E3: 8 | F3: 0 | G3: 0 | H3: =$B3*D3 -> 167 | I3: =$B3*E3 -> 334 | J3: =$B3*F3 -> 0 | K3: =$B3*G3 -> 0
A4: O2 | B4: =r1!D8 -> 83.5 | C4: o2 | D4: 0 | E4: 0 | F4: 2 | G4: 0 | H4: =$B4*D4 -> 0 | I4: =$B4*E4 -> 0 | J4: =$B4*F4 -> 167 | K4: =$B4*G4 -> 0
A5: N2 | B5: =r1!D9 -> 296.04545 | C5: n2 | D5: 0 | E5: 0 | F5: 0 | G5: 2 | H5: =$B5*D5 -> 0 | I5: =$B5*E5 -> 0 | J5: =$B5*F5 -> 0 | K5: =$B5*G5 -> 592.09091
A6: H2O | B6: =r1!D10 -> 62.625 | C6: h2o | D6: 0 | E6: 2 | F6: 1 | G6: 0 | H6: =$B6*D6 -> 0 | I6: =$B6*E6 -> 125.25 | J6: =$B6*F6 -> 62.625 | K6: =$B6*G6 -> 0
H7: =SUM(H3:H6) -> 167 | I7: =SUM(I3:I6) -> 459.25 | J7: =SUM(J3:J6) -> 229.625 | K7: =SUM(K3:K6) -> 592.09091
B9: flow | D9: number of atoms | H9: elemental flow (kmol/h)
B10: kmol/h | C10: formula | D10: C | E10: H | F10: O | G10: N | H10: C | I10: H | J10: O | K10: N
A11: IB | B11: =r1!M6 -> 0.167 | C11: c4h8 | D11: 4 | E11: 8 | F11: 0 | G11: 0 | H11: =$B11*D11 -> 0.668 | I11: =$B11*E11 -> 1.336 | J11: =$B11*F11 -> 0 | K11: =$B11*G11 -> 0
A12: MAC | B12: =r1!M7 -> 34.466502 | C12: C4H6O | D12: 4 | E12: 6 | F12: 1 | G12: 0 | H12: =$B12*D12 -> 137.86601 | I12: =$B12*E12 -> 206.79901 | J12: =$B12*F12 -> 34.466502 | K12: =$B12*G12 -> 0
A13: CO | B13: =r1!M8 -> 5.1234208 | C13: CO | D13: 1 | E13: 0 | F13: 1 | G13: 0 | H13: =$B13*D13 -> 5.1234208 | I13: =$B13*E13 -> 0 | J13: =$B13*F13 -> 5.1234208 | K13: =$B13*G13 -> 0
A14: MAA | B14: =r1!M9 -> 1.4539438 | C14: C4H6O2 | D14: 4 | E14: 6 | F14: 2 | G14: 0 | H14: =$B14*D14 -> 5.815775 | I14: =$B14*E14 -> 8.7236625 | J14: =$B14*F14 -> 2.9078875 | K14: =$B14*G14 -> 0
A15: Acetic ac | B15: =r1!M10 -> 1.4539438 | C15: C2H4O2 | D15: 2 | E15: 4 | F15: 2 | G15: 0 | H15: =$B15*D15 -> 2.9078875 | I15: =$B15*E15 -> 5.815775 | J15: =$B15*F15 -> 2.9078875 | K15: =$B15*G15 -> 0
A16: acetone | B16: =r1!M11 -> 0.830825 | C16: C3H6O | D16: 3 | E16: 2 | F16: 1 | G16: 0 | H16: =$B16*D16 -> 2.492475 | I16: =$B16*E16 -> 1.66165 | J16: =$B16*F16 -> 0.830825 | K16: =$B16*G16 -> 0
A17: acetalde | B17: =r1!M12 -> 1.4539438 | C17: C2H4O | D17: 2 | E17: 4 | F17: 1 | G17: 0 | H17: =$B17*D17 -> 2.9078875 | I17: =$B17*E17 -> 5.815775 | J17: =$B17*F17 -> 1.4539438 | K17: =$B17*G17 -> 0
A18: acrolein | B18: =r1!M13 -> 0.27694167 | C18: C3H4O | D18: 3 | E18: 4 | F18: 1 | G18: 0 | H18: =$B18*D18 -> 0.830825 | I18: =$B18*E18 -> 1.1077667 | J18: =$B18*F18 -> 0.27694167 | K18: =$B18*G18 -> 0
A19: formaldehyde | B19: =r1!M14 -> 0.20770625 | C19: CH2O | D19: 1 | E19: 2 | F19: 1 | G19: 0 | H19: =$B19*D19 -> 0.20770625 | I19: =$B19*E19 -> 0.4154125 | J19: =$B19*F19 -> 0.20770625 | K19: =$B19*G19 -> 0
A20: acrylic acid | B20: =r1!M15 -> 0.20770625 | C20: C3H4O2 | D20: 3 | E20: 4 | F20: 2 | G20: 0 | H20: =$B20*D20 -> 0.62311875 | I20: =$B20*E20 -> 0.830825 | J20: =$B20*F20 -> 0.4154125 | K20: =$B20*G20 -> 0
A21: O2 | B21: =r1!M16 -> 26.35 | C21: O2 | D21: 0 | E21: 0 | F21: 2 | G21: 0 | H21: =$B21*D21 -> 0 | I21: =$B21*E21 -> 0 | J21: =$B21*F21 -> 52.7 | K21: =$B21*G21 -> 0
A22: N2 | B22: =r1!M17 -> 296.04545 | C22: N2 | D22: 0 | E22: 0 | F22: 0 | G22: 2 | H22: =$B22*D22 -> 0 | I22: =$B22*E22 -> 0 | J22: =$B22*F22 -> 0 | K22: =$B22*G22 -> 592.09091
A23: CO2 | B23: 0 | C23: CO2 | D23: 1 | E23: 0 | F23: 2 | G23: 0 | H23: =$B23*D23 -> 0 | I23: =$B23*E23 -> 0 | J23: =$B23*F23 -> 0 | K23: =$B23*G23 -> 0
A24: steam | B24: 0 | C24: H2O | D24: 0 | E24: 2 | F24: 1 | G24: 0 | H24: =$B24*D24 -> 0 | I24: =$B24*E24 -> 0 | J24: =$B24*F24 -> 0 | K24: =$B24*G24 -> 0
A25: formic acid | B25: 0 | C25: CH2O2 | D25: 1 | E25: 2 | F25: 2 | G25: 0 | H25: 0 | I25: 0 | J25: 0 | K25: 0
H26: =SUM(H11:H25) -> 159.4431 | I26: =SUM(I11:I25) -> 232.50588 | J26: =SUM(J11:J25) -> 101.29053 | K26: =SUM(K11:K25) -> 592.09091
G28: uncounted | H28: =H7-H26 -> 7.5568959 | I28: =I7-I26 -> 226.74412 | J28: =J7-J26 -> 128.33447 | K28: =K7-K26 -> 0
G29: let flow rates
G30: CO2 | H30: X
G31: H2O | H31: Y
F34: C | G34: X | H34: =H28 -> 7.5568959
F35: H | G35: 2Y | H35: =I28 -> 226.74412 | I35: =H35/2 -> 113.37206
F36: O | G36: 2X + Y | H36: =J28 -> 128.33447 | I36: =I35+H34 -> 120.92896

Sheet r2
N1: 0.7 vol% methacrolein, 1 mol% CO, 2.28 mol% methacrylic acid, 0.31 mol% acetic acid, 0.12 mol% acetone, 0.21 mol% acetaldehyde, 0.04 mol% acrolein, 0.03 mol% formaldehyde, 0.03 mol% acrylic acid and 6.5 vol% oxygen
I2: C4H6O + 0.5 O2 → C4H6O2
U3: for figuring out how much makeup air we need to add
B5: PG3_1 | C5: =r1!L5 -> mol% | D5: =r1!M5 -> kmol/h | E5: =r1!N5 -> mw | F5: =r1!O5 -> kg/h | N5: ='stream compositions'!C67 -> mol% | O5: ='stream compositions'!D67 -> kmol/h | P5: ='stream compositions'!E67 -> mw | Q5: ='stream compositions'!F67 -> kg/h | R5: ='stream compositions'!G67 -> wt% | U5: side reactions
B6: =r1!K6 -> IB | C6: =r1!L6 -> 0.03415368 | D6: =r1!M6 -> 0.167 | E6: =r1!N6 -> 56 | F6: =r1!O6 -> 3.6066307 | M6: ='stream compositions'!B68 -> MAC | N6: 0.7 | O6: =D7*(1-J7) -> 7.5826305 | P6: 70 | Q6: =O6*P6 -> 530.78413 | R6: =Q6/$Q$20*100 -> 1.5557564
B7: =r1!K7 -> MAC | C7: =r1!L7 -> 7.0488496 | D7: =r1!M7 -> 34.466502 | E7: =r1!N7 -> 70 | F7: =r1!O7 -> 2412.6551 | I7: conv | J7: 0.78 | M7: ='stream compositions'!B69 -> CO | N7: 1 | O7: =N7/100*$O$20 -> 10.832329 | P7: 28 | Q7: =O7*P7 -> 303.30522 | R7: =Q7/$Q$20*100 -> 0.88900366 | U7: IB + O2 → Acetone + Formaldehyde
B8: =r1!K8 -> CO | C8: =r1!L8 -> 1.0478064 | D8: =r1!M8 -> 5.1234208 | E8: =r1!N8 -> 28 | F8: =r1!O8 -> 143.45578 | I8: selectivity | J8: 0.85 | M8: ='stream compositions'!B70 -> MAA | N8: 2.28 | O8: =N8/100*$O$20 -> 24.697711 | P8: 86 | Q8: =O8*P8 -> 2124.0031 | R8: =Q8/$Q$20*100 -> 6.2255656 | U8: MAC +3O2 → Acetic acid + CO2 + H2O
B9: =r1!K9 -> MAA | C9: =r1!L9 -> 0.29735048 | D9: =r1!M9 -> 1.4539438 | E9: =r1!N9 -> 86 | F9: =r1!O9 -> 125.03916 | I9: yield | J9: =J8*J7 -> 0.663 | M9: ='stream compositions'!B71 -> Acetic ac | N9: 0.31 | O9: =N9/100*$O$20 -> 3.3580221 | P9: 60 | Q9: =O9*P9 -> 201.48132 | R9: =Q9/$Q$20*100 -> 0.59055243 | U9: MAC + 2O2 → Acryclic acid + H2O
B10: =r1!K10 -> Acetic ac | C10: =r1!L10 -> 0.29735048 | D10: =r1!M10 -> 1.4539438 | E10: =r1!N10 -> 60 | F10: =r1!O10 -> 87.236625 | M10: ='stream compositions'!B72 -> acetone | N10: 0.12 | O10: =N10/100*$O$20 -> 1.2998795 | P10: 58 | Q10: =O10*P10 -> 75.393011 | R10: =Q10/$Q$20*100 -> 0.22098091 | U10: IB + 2.5 O2 → Acroelin + CO2 + 2H2O
B11: =r1!K11 -> acetone | C11: =r1!L11 -> 0.16991456 | D11: =r1!M11 -> 0.830825 | E11: =r1!N11 -> 58 | F11: =r1!O11 -> 48.18785 | M11: ='stream compositions'!B73 -> acetaldehyde | N11: 0.21 | O11: =N11/100*$O$20 -> 2.2747891 | P11: 44 | Q11: =O11*P11 -> 100.09072 | R11: =Q11/$Q$20*100 -> 0.29337121 | U11: MAC + 1.5O2 → Acrolein + CO2 + H2O
B12: =r1!K12 -> acetalde | C12: =r1!L12 -> 0.29735048 | D12: =r1!M12 -> 1.4539438 | E12: =r1!N12 -> 44 | F12: =r1!O12 -> 63.973525 | M12: ='stream compositions'!B74 -> acrolein | N12: 0.04 | O12: =N12/100*$O$20 -> 0.43329317 | P12: 56 | Q12: =O12*P12 -> 24.264417 | R12: =Q12/$Q$20*100 -> 0.071120293 | U12: MAC + 2.5O2 → Acetaldehyde + 2CO2 + H2O
B13: =r1!K13 -> acrolein | C13: =r1!L13 -> 0.056638186 | D13: =r1!M13 -> 0.27694167 | E13: =r1!N13 -> 56 | F13: =r1!O13 -> 15.508733 | M13: ='stream compositions'!B75 -> formaldehyde | N13: 0.03 | O13: =N13/100*$O$20 -> 0.32496988 | P13: 30 | Q13: =O13*P13 -> 9.7490963 | R13: =Q13/$Q$20*100 -> 0.028575118
B14: =r1!K14 -> formaldehyde | C14: =r1!L14 -> 0.042478639 | D14: =r1!M14 -> 0.20770625 | E14: =r1!N14 -> 30 | F14: =r1!O14 -> 6.2311875 | M14: ='stream compositions'!B76 -> acrylic acid | N14: 0.03 | O14: =N14/100*$O$20 -> 0.32496988 | P14: 72 | Q14: =O14*P14 -> 23.397831 | R14: =Q14/$Q$20*100 -> 0.068580282 | U14: so based on this
B15: =r1!K15 -> acrylic acid | C15: =r1!L15 -> 0.042478639 | D15: =r1!M15 -> 0.20770625 | E15: =r1!N15 -> 72 | F15: =r1!O15 -> 14.95485 | M15: ='stream compositions'!B77 -> oxygen | N15: 6.5 | O15: =N15/100*$O$20 -> 70.41014 | P15: 32 | Q15: =O15*P15 -> 2253.1245 | R15: =Q15/$Q$20*100 -> 6.6040272
B16: =r1!K16 -> O2 | C16: =r1!L16 -> 5.388919 | D16: =r1!M16 -> 26.35 | E16: =r1!N16 -> 32 | F16: =r1!O16 -> 843.2 | M16: ='stream compositions'!B78 -> steam | N16: =O16/$O$20*100 -> 18.983771 | O16: =Q16/P16 -> 205.63846 | P16: 18 | Q16: =quencher!F22 -> 3701.4923 | R16: =Q16/$Q$20*100 -> 10.84927 | U16: IB/MAC | V16: product | W16: moles of O2 per mole | X16: product moles | Y16: Reactant moles | Z16: product in system | AA16: moles O2 | AC16: now we can also see that some moles of Formaldehyde get converted to CO2 and O2
B17: =r1!K17 -> N2 | C17: =r1!L17 -> 60.54516 | D17: =r1!M17 -> 296.04545 | E17: =r1!N17 -> 28 | F17: =r1!O17 -> 8289.2727 | M17: ='stream compositions'!B79 -> CO2 | N17: =O17/$O$20*100 -> 3.3235859 | O17: =Q17/P17 -> 36.002176 | P17: 44 | Q17: =quencher!F23 -> 1584.0958 | R17: =Q17/$Q$20*100 -> 4.6430686 | U17: IB | V17: Acetone | W17: 1 | X17: 1 | Y17: 1 | Z17: =Q26 -> 0.46905451 | AA17: =W17*Z17 -> 0.46905451 | AC17: reactant | AD17: product | AE17: O2 per mole reactant | AF17: Reacting moles | AG17: moles O2 used
B18: =r1!K18 -> CO2 | C18: =r1!L18 -> 1.5454839 | D18: =r1!M18 -> 7.5568959 | E18: =r1!N18 -> 44 | F18: =r1!O18 -> 332.50342 | M18: ='stream compositions'!B80 -> N2 | N18: =O18/$O$20*100 -> 76.425265 | O18: =I23+D17 -> 827.86364 | P18: 28 | Q18: =O18*P18 -> 23180.182 | R18: =Q18/$Q$20*100 -> 67.942341 | U18: MAC | V18: Acetic acid | W18: 3 | X18: 1 | Y18: 1 | Z18: =Q27 -> 1.9040783 | AA18: =W18*Z18 -> 5.7122349 | AC18: formaldehyde | AD18: CO, CO2 | AE18: 0.5 | AF18: =O10-O13 -> 0.97490963 | AG18: =AF18*AE18 -> 0.48745481
B19: =r1!K19 -> steam | C19: =r1!L19 -> 23.186066 | D19: =r1!M19 -> 113.37206 | E19: =r1!N19 -> 18 | F19: =r1!O19 -> 2040.6971 | M19: Impurity | N19: =O19/$O$20*100 -> 0.0033748709 | O19: =Q19/P19 -> 0.036557713 | P19: 166 | Q19: =quencher!F25 -> 6.0685803 | R19: =Q19/$Q$20*100 -> 0.01778733 | U19: MAC | V19: Acryclic acid | W19: 2 | X19: 1 | Y19: 1 | Z19: =Q28 -> 0.11726363 | AA19: =W19*Z19 -> 0.23452725
B20: =r1!K20 -> formic acid | C20: =r1!L20 -> 0 | D20: =r1!M20 -> 0 | E20: =r1!N20 -> 46 | F20: =r1!O20 -> 0 | M20: ='stream compositions'!B82 -> Total | O20: =O6/N6% -> 1083.2329 | Q20: =F21+K24 -> 34117.432 | V20: Acrolein | W20: =4 -> 4 | X20: 2 | Y20: 1 | Z20: =Q29 -> 0.1563515 | AA20: =W20*Z20 -> 0.62540601
B21: =r1!K21 -> total | C21: =r1!L21 -> 100 | D21: =r1!M21 -> 488.96634 | E21: =r1!N21 -> 0 | F21: =r1!O21 -> 14426.523 | H21: =U35 -> PG 3 | I21: =V35 -> kmol/h | J21: =W35 -> MW | K21: =X35 -> kg/h | L21: =Y35 -> 0 | U21: MAC | V21: Acetaldehyde | W21: 2.5 | X21: 1 | Y21: 1 | Z21: =Q30 -> 0.82084539 | AA21: =W21*Z21 -> 2.0521135
H22: =U36 -> O2 | I22: =V36 -> 150 | J22: =W36 -> 32 | K22: =X36 -> 4800 | L22: =Y36 -> 0 | R22: =SUM(Q6:Q19) -> 34117.432 | V22: formaldehyde | W22: 1 | X22: 1 | Y22: 1 | Z22: =Q31 -> 0.11726363 | AA22: =W22*Z22 -> 0.11726363
H23: =U37 -> N2 | I23: =V37 -> 531.81818 | J23: =W37 -> 28 | K23: =X37 -> 14890.909 | L23: =Y37 -> 0
I24: =V38 -> 681.81818 | K24: =X38 -> 19690.909 | L24: =Y38 -> 472581.82 | AA24: =SUM(AA17:AA22) -> 9.2105998
N25: Side products | O25: In | P25: out | Q25: difference | U25: Moles of O2 to given MAA
N26: Acetone | O26: =D11 -> 0.830825 | P26: =O10 -> 1.2998795 | Q26: =P26-O26 -> 0.46905451 | U26: =D7*J7*0.5 -> 13.441936
N27: Acetic acid | O27: =D10 -> 1.4539438 | P27: =O9 -> 3.3580221 | Q27: =P27-O27 -> 1.9040783 | U27: moles of O2 remaining unreacted
N28: Acryclic acid | O28: =D15 -> 0.20770625 | P28: =O14 -> 0.32496988 | Q28: =P28-O28 -> 0.11726363 | U28: =D16-U26-AG18 -> 12.420609
N29: Acrolein | O29: =D13 -> 0.27694167 | P29: =O12 -> 0.43329317 | Q29: =P29-O29 -> 0.1563515
N30: Acetaldehyde | O30: =D12 -> 1.4539438 | P30: =O11 -> 2.2747891 | Q30: =P30-O30 -> 0.82084539 | U30: moles of O2 added
N31: Formaldehyde | O31: =D14 -> 0.20770625 | P31: =O13 -> 0.32496988 | Q31: =P31-O31 -> 0.11726363 | U31: =O15-U28 -> 57.989531
U33: hence air added to the system is such that there is 5.4 moles of O2 in the air
U34: recycle air composition
U35: PG 3 | V35: kmol/h | W35: MW | X35: kg/h
U36: O2 | V36: 150 | W36: 32 | X36: =V36*W36 -> 4800
U37: N2 | V37: =V36/0.22*0.78 -> 531.81818 | W37: 28 | X37: =V37*W37 -> 14890.909
V38: =SUM(V36:V37) -> 681.81818 | X38: =SUM(X36:X37) -> 19690.909 | Y38: =X38*24 -> 472581.82
Y39: =Y38+r1!G12 -> 735652.36
G41: Cp | M41: cooling req (T1 → T2)
A42: INLET | B42: kmol/h | C42: mol/h | D42: T_1 | E42: T_2 | F42: H @ T1 | G42: A | H42: B | I42: C | J42: D | K42: E | L42: H@ T2 | M42: ΔH (J/h) | P42: outlet | Q42: kmol/h | R42: mol/h | S42: T | T42: T_amb | U42: A | V42: B | W42: C | X42: D | Y42: E | Z42: Sensible heat at T (J/h) | AA42: ΔH_form (kJ/molh) | AB42: ΔH_form (kJ/h)
A43: =B6 -> IB | B43: =D6 -> 0.167 | C43: =B43*1000 -> 167 | D43: =r1!O27 -> 623.15 | E43: =245+273.15 -> 518.15 | F43: =r1!AA27 -> 1.89756e-05 | G43: =r1!V27 -> IB + O2 → MAC + H2O | H43: =r1!W27 -> 0 | I43: =r1!X27 -> 0 | J43: =r1!Y27 -> -333.418 | K43: =r1!Z27 -> -0.01744 | L43: =C43*(G43*E43+H43/2*E43^2+I43/3*E43^3+J43/4*E43^4+K43/5*E43^5) -> #VALUE! | M43: =-(L43-F43) -> #VALUE! | P43: =M6 -> MAC | Q43: =O6 -> 7.5826305 | R43: =Q43*1000 -> 7582.6305 | S43: =305+273.15 -> 578.15 | T43: 298 | U43: 14.506 | V43: 0.15922 | W43: 0.0003118 | X43: -4.21e-07 | Y43: 1.4222e-10 | Z43: =R43*(U43*S43+V43/2*S43^2+W43/3*S43^3+X43/4*S43^4+Y43/5*S43^5) -> 3.4243214e+08 | AA43: ='heat of reactions'!Q9 -> -337.17153 | AB43: =R43*AA43 -> -2556647.1
...

Sheet gas cooler
F3: JP2001253846A | H3: patent for gas cooler design
T5: =T8-273.15 -> 180
B7: =r2!M5 -> 0 | C7: =r2!N5 -> mol% | D7: =r2!O5 -> kmol/h | E7: =r2!P5 -> mw | F7: =r2!Q5 -> kg/h | G7: =r2!R5 -> wt% | H7: H @ T1 (J/h) | I7: T1 | N7: PG4_2 | O7: =C7 -> mol% | P7: =D7 -> kmol/h | Q7: =E7 -> mw | R7: =F7 -> kg/h | S7: =G7 -> wt% | T7: Tf | U7: A | V7: B | W7: C | X7: D | Y7: E | Z7: H @ T2 (J/h)
B8: =r2!M6 -> MAC | C8: =r2!N6 -> 0.7 | D8: =r2!O6 -> 7.5826305 | E8: =r2!P6 -> 70 | F8: =r2!Q6 -> 530.78413 | G8: =r2!R6 -> 1.5557564 | H8: =r2!Z43 -> 3.4243214e+08 | I8: =r2!S43 -> 578.15 | N8: =B8 -> MAC | O8: =C8 -> 0.7 | P8: =D8 -> 7.5826305 | Q8: =E8 -> 70 | R8: =F8 -> 530.78413 | S8: =G8 -> 1.5557564 | T8: =453.15 -> 453.15 | U8: 14.506 | V8: 0.15922 | W8: 0.0003118 | X8: -4.21e-07 | Y8: 1.4222e-10 | Z8: =P8*1000*(U8*T8+V8/2*T8^2+W8/3*T8^3+X8/4*T8^4+Y8/5*T8^5) -> 2.1760319e+08
B9: =r2!M7 -> CO | C9: =r2!N7 -> 1 | D9: =r2!O7 -> 10.832329 | E9: =r2!P7 -> 28 | F9: =r2!Q7 -> 303.30522 | G9: =r2!R7 -> 0.88900366 | H9: =r2!Z44 -> 1.8390785e+08 | I9: =r2!S44 -> 578.15 | N9: =B9 -> CO | O9: =C9 -> 1 | P9: =D9 -> 10.832329 | Q9: =E9 -> 28 | R9: =F9 -> 303.30522 | S9: =G9 -> 0.88900366 | T9: =453.15 -> 453.15 | U9: 29.556 | V9: -0.0065807 | W9: 2.013e-05 | X9: -1.2227e-08 | Y9: 2.6717e-12 | Z9: =P9*1000*(U9*T9+V9/2*T9^2+W9/3*T9^3+X9/4*T9^4+Y9/5*T9^5) -> 1.4323959e+08
B10: =r2!M8 -> MAA | C10: =r2!N8 -> 2.28 | D10: =r2!O8 -> 24.697711 | E10: =r2!P8 -> 86 | F10: =r2!Q8 -> 2124.0031 | G10: =r2!R8 -> 6.2255656 | H10: =r2!Z45 -> 1.1785887e+09 | I10: =r2!S45 -> 578.15 | N10: =B10 -> MAA | O10: =C10 -> 2.28 | P10: =D10 -> 24.697711 | Q10: =E10 -> 86 | R10: =F10 -> 2124.0031 | S10: =G10 -> 6.2255656 | T10: =453.15 -> 453.15 | U10: -28.131 | V10: 0.54744 | W10: -0.00053877 | X10: 2.8583e-07 | Y10: -6.0864e-11 | Z10: =P10*1000*(U10*T10+V10/2*T10^2+W10/3*T10^3+X10/4*T10^4+Y10/5*T10^5) -> 7.2929257e+08
B11: =r2!M9 -> Acetic ac | C11: =r2!N9 -> 0.31 | D11: =r2!O9 -> 3.3580221 | E11: =r2!P9 -> 60 | F11: =r2!Q9 -> 201.48132 | G11: =r2!R9 -> 0.59055243 | H11: =r2!Z46 -> 1.2517721e+08 | I11: =r2!S46 -> 578.15 | N11: =B11 -> Acetic ac | O11: =C11 -> 0.31 | P11: =D11 -> 3.3580221 | Q11: =E11 -> 60 | R11: =F11 -> 201.48132 | S11: =G11 -> 0.59055243 | T11: =453.15 -> 453.15 | U11: 34.85 | V11: 0.037626 | W11: 0.00028311 | X11: -3.0767e-07 | Y11: 9.2646e-11 | Z11: =P11*1000*(U11*T11+V11/2*T11^2+W11/3*T11^3+X11/4*T11^4+Y11/5*T11^5) -> 85788936
B12: =r2!M10 -> acetone | C12: =r2!N10 -> 0.12 | D12: =r2!O10 -> 1.2998795 | E12: =r2!P10 -> 58 | F12: =r2!Q10 -> 75.393011 | G12: =r2!R10 -> 0.22098091 | H12: =r2!Z47 -> 56278071 | I12: =r2!S47 -> 578.15 | N12: =B12 -> acetone | O12: =C12 -> 0.12 | P12: =D12 -> 1.2998795 | Q12: =E12 -> 58 | R12: =F12 -> 75.393011 | S12: =G12 -> 0.22098091 | T12: =453.15 -> 453.15 | U12: 35.918 | V12: 0.093896 | W12: 0.0001873 | X12: -2.1643e-07 | Y12: 6.3174e-11 | Z12: =P12*1000*(U12*T12+V12/2*T12^2+W12/3*T12^3+X12/4*T12^4+Y12/5*T12^5) -> 38588511
B13: =r2!M11 -> acetaldehyde | C13: =r2!N11 -> 0.21 | D13: =r2!O11 -> 2.2747891 | E13: =r2!P11 -> 44 | F13: =r2!Q11 -> 100.09072 | G13: =r2!R11 -> 0.29337121 | H13: =r2!Z48 -> 73963554 | I13: =r2!S48 -> 578.15 | N13: =B13 -> acetaldehyde | O13: =C13 -> 0.21 | P13: =D13 -> 2.2747891 | Q13: =E13 -> 44 | R13: =F13 -> 100.09072 | S13: =G13 -> 0.29337121 | T13: =453.15 -> 453.15 | U13: 34.14 | V13: 0.04002 | W13: 0.00015634 | X13: =0.00000016445 -> 1.6445e-07 | Y13: 4.7248e-11 | Z13: =P13*1000*(U13*T13+V13/2*T13^2+W13/3*T13^3+X13/4*T13^4+Y13/5*T13^5) -> 59924493
B14: =r2!M12 -> acrolein | C14: =r2!N12 -> 0.04 | D14: =r2!O12 -> 0.43329317 | E14: =r2!P12 -> 56 | F14: =r2!Q12 -> 24.264417 | G14: =r2!R12 -> 0.071120293 | H14: =r2!Z49 -> 19909478 | I14: =r2!S49 -> 578.15 | N14: =B14 -> acrolein | O14: =C14 -> 0.04 | P14: =D14 -> 0.43329317 | Q14: =E14 -> 56 | R14: =F14 -> 24.264417 | S14: =G14 -> 0.071120293 | T14: =453.15 -> 453.15 | U14: 109.243 | V14: -0.50952 | W14: 0.0017059 | X14: -1.8068e-06 | Y14: 6.5983e-10 | Z14: =P14*1000*(U14*T14+V14/2*T14^2+W14/3*T14^3+X14/4*T14^4+Y14/5*T14^5) -> 14548790
B15: =r2!M13 -> formaldehyde | C15: =r2!N13 -> 0.03 | D15: =r2!O13 -> 0.32496988 | E15: =r2!P13 -> 30 | F15: =r2!Q13 -> 9.7490963 | G15: =r2!R13 -> 0.028575118 | H15: =r2!Z50 -> 6999321.4 | I15: =r2!S50 -> 578.15 | N15: =B15 -> formaldehyde | O15: =C15 -> 0.03 | P15: =D15 -> 0.32496988 | Q15: =E15 -> 30 | R15: =F15 -> 9.7490963 | S15: =G15 -> 0.028575118 | T15: =453.15 -> 453.15 | U15: 34.428 | V15: -0.029779 | W15: 0.00015104 | X15: -1.2733e-07 | Y15: 3.3887e-11 | Z15: =P15*1000*(U15*T15+V15/2*T15^2+W15/3*T15^3+X15/4*T15^4+Y15/5*T15^5) -> 5204607.1
B16: =r2!M14 -> acrylic acid | C16: =r2!N14 -> 0.03 | D16: =r2!O14 -> 0.32496988 | E16: =r2!P14 -> 72 | F16: =r2!Q14 -> 23.397831 | G16: =r2!R14 -> 0.068580282 | H16: =r2!Z51 -> 13658220 | I16: =r2!S51 -> 578.15 | N16: =B16 -> acrylic acid | O16: =C16 -> 0.03 | P16: =D16 -> 0.32496988 | Q16: =E16 -> 72 | R16: =F16 -> 23.397831 | S16: =G16 -> 0.068580282 | T16: =453.15 -> 453.15 | U16: 7.755 | V16: 0.29386 | W16: -0.00020878 | X16: 7.1591e-08 | Y16: -9.096e-12 | Z16: =P16*1000*(U16*T16+V16/2*T16^2+W16/3*T16^3+X16/4*T16^4+Y16/5*T16^5) -> 9076288.6
B17: =r2!M15 -> oxygen | C17: =r2!N15 -> 6.5 | D17: =r2!O15 -> 70.41014 | E17: =r2!P15 -> 32 | F17: =r2!Q15 -> 2253.1245 | G17: =r2!R15 -> 6.6040272 | H17: =r2!Z52 -> 1.2151702e+09 | I17: =r2!S52 -> 578.15 | N17: =B17 -> oxygen | O17: =C17 -> 6.5 | P17: =D17 -> 70.41014 | Q17: =E17 -> 32 | R17: =F17 -> 2253.1245 | S17: =G17 -> 6.6040272 | T17: =453.15 -> 453.15 | U17: 31.32234 | V17: -0.02023531 | W17: 5.786644e-05 | X17: -3.650624e-08 | Y17: 7.374e-15 | Z17: =P17*1000*(U17*T17+V17/2*T17^2+W17/3*T17^3+X17/4*T17^4+Y17/5*T17^5) -> 9.5237922e+08
B18: =r2!M16 -> steam | C18: =r2!N16 -> 18.983771 | D18: =r2!O16 -> 205.63846 | E18: =r2!P16 -> 18 | F18: =r2!Q16 -> 3701.4923 | G18: =r2!R16 -> 10.84927 | H18: =r2!Z53 -> 4.0485392e+09 | I18: =r2!S53 -> 578.15 | N18: =B18 -> steam | O18: =C18 -> 18.983771 | P18: =D18 -> 205.63846 | Q18: =E18 -> 18 | R18: =F18 -> 3701.4923 | S18: =G18 -> 10.84927 | T18: =453.15 -> 453.15 | U18: 30.092 | V18: 0.006832514 | W18: 6.793435e-06 | X18: -2.53448e-09 | Y18: 8.2139e-14 | Z18: =P18*1000*(U18*T18+V18/2*T18^2+W18/3*T18^3+X18/4*T18^4+Y18/5*T18^5) -> 2.9862841e+09
B19: =r2!M17 -> CO2 | C19: =r2!N17 -> 3.3235859 | D19: =r2!O17 -> 36.002176 | E19: =r2!P17 -> 44 | F19: =r2!Q17 -> 1584.0958 | G19: =r2!R17 -> 4.6430686 | H19: =r2!Z54 -> 7.8423031e+08 | I19: =r2!S54 -> 578.15 | N19: =B19 -> CO2 | O19: =C19 -> 3.3235859 | P19: =D19 -> 36.002176 | Q19: =E19 -> 44 | R19: =F19 -> 1584.0958 | S19: =G19 -> 4.6430686 | T19: =453.15 -> 453.15 | U19: 27.437 | V19: 0.042315 | W19: -1.9555e-05 | X19: 3.9968e-09 | Y19: -2.9872e-13 | Z19: =P19*1000*(U19*T19+V19/2*T19^2+W19/3*T19^3+X19/4*T19^4+Y19/5*T19^5) -> 5.836712e+08
B20: =r2!M18 -> N2 | C20: =r2!N18 -> 76.425265 | D20: =r2!O18 -> 827.86364 | E20: =r2!P18 -> 28 | F20: =r2!Q18 -> 23180.182 | G20: =r2!R18 -> 67.942341 | H20: =r2!Z55 -> 9.5871157e+09 | I20: =r2!S55 -> 578.15 | N20: =B20 -> N2 | O20: =C20 -> 76.425265 | P20: =D20 -> 827.86364 | Q20: =E20 -> 28 | R20: =F20 -> 23180.182 | S20: =G20 -> 67.942341 | T20: =453.15 -> 453.15 | U20: 28.98641 | V20: 0.001853978 | W20: -9.647459e-06 | X20: 1.663537e-08 | Y20: 1.17e-16 | Z20: =P20*1000*(U20*T20+V20/2*T20^2+W20/3*T20^3+X20/4*T20^4+Y20/5*T20^5) -> 1.0929183e+10
B21: =r2!M19 -> Impurity | C21: =r2!N19 -> 0.0033748709 | D21: =r2!O19 -> 0.036557713 | E21: =r2!P19 -> 166 | F21: =r2!Q19 -> 6.0685803 | G21: =r2!R19 -> 0.01778733 | H21: =r2!Z56 -> 2314189.6 | I21: =r2!S56 -> 578.15 | N21: =B21 -> Impurity | O21: =C21 -> 0.0033748709 | P21: =D21 -> 0.036557713 | Q21: =E21 -> 166 | R21: =F21 -> 6.0685803 | S21: =G21 -> 0.01778733 | T21: =453.15 -> 453.15 | U21: -48.374 | V21: 0.69316 | W21: -0.00041468 | X21: 7.2672e-08 | Y21: 8.1593e-12 | Z21: =P21*1000*(U21*T21+V21/2*T21^2+W21/3*T21^3+X21/4*T21^4+Y21/5*T21^5) -> 1359316.4
B22: =r2!M20 -> Total | C22: =r2!N20 -> 0 | D22: =r2!O20 -> 1083.2329 | E22: =r2!P20 -> 0 | F22: =r2!Q20 -> 34117.432 | H22: =SUM(H8:H21) -> 1.7638284e+10 | N22: =B22 -> Total | O22: =C22 -> 0 | P22: =D22 -> 1083.2329 | Q22: =E22 -> 0 | R22: =F22 -> 34117.432 | S22: =G22 -> 0 | Z22: =SUM(Z8:Z21) -> 1.6756143e+10
J25: cooling required
K26: =H22-Z22 -> 8.8214083e+08 | L26: J/h | O26: cp
K27: =K26/1000 -> 882140.83 | L27: kJ/h | N27: species | O27: A | P27: B | Q27: C | R27: D | S27: E
K28: =K27/3600 -> 245.03912 | L28: kW | N28: MAC | O28: 14.506 | P28: 0.15922 | Q28: 0.0003118 | R28: -4.21e-07 | S28: 1.4222e-10
N29: CO | O29: 29.556 | P29: -0.0065807 | Q29: 2.013e-05 | R29: -1.2227e-08 | S29: 2.6717e-12
N30: MAA | O30: -28.131 | P30: 0.54744 | Q30: -0.00053877 | R30: 2.8583e-07 | S30: -6.0864e-11
N31: Acetic ac | O31: 34.85 | P31: 0.037626 | Q31: 0.00028311 | R31: -3.0767e-07 | S31: 9.2646e-11
N32: acetone | O32: 35.918 | P32: 0.093896 | Q32: 0.0001873 | R32: -2.1643e-07 | S32: 6.3174e-11
N33: acetaldehyde | O33: 34.14 | P33: 0.04002 | Q33: 0.00015634 | R33: 1.6445e-07 | S33: 4.7248e-11
N34: acrolein | O34: 109.243 | P34: -0.50952 | Q34: 0.0017059 | R34: -1.8068e-06 | S34: 6.5983e-10
N35: formaldehyde | O35: 34.428 | P35: -0.029779 | Q35: 0.00015104 | R35: -1.2733e-07 | S35: 3.3887e-11
N36: acrylic acid | O36: 7.755 | P36: 0.29386 | Q36: -0.00020878 | R36: 7.1591e-08 | S36: -9.096e-12
N37: oxygen | O37: 31.32234 | P37: -0.02023531 | Q37: 5.786644e-05 | R37: -3.650624e-08 | S37: 7.374e-15
N38: steam | O38: 30.092 | P38: 0.006832514 | Q38: 6.793435e-06 | R38: -2.53448e-09 | S38: 8.2139e-14
N39: CO2 | O39: 27.437 | P39: 0.042315 | Q39: -1.9555e-05 | R39: 3.9968e-09 | S39: -2.9872e-13
N40: N2 | O40: 28.98641 | P40: 0.001853978 | Q40: -9.647459e-06 | R40: 1.663537e-08 | S40: 1.17e-16
N41: Impurity | O41: -48.374 | P41: 0.69316 | Q41: -0.00041468 | R41: 7.2672e-08 | S41: 8.1593e-12
N42: Total

Sheet quencher
X1: DO THE MAT BALANCE FOR WATER AGAIN, WATER IN LIQUID STREAM, is the total liquid water added
I2: cooling water | L2: CW in
I3: At 25 deg C? | L3: Flow rate | M3: 0 | N3: kg/h
L4: Molflow rate | M4: =M3/18 -> 0 | N4: kmol/h
E9: Tin | F9: =453.15 -> 453.15 | G9: =F9-273.15 -> 180
B11: =r2!M5 -> 0 | C11: =r2!N5 -> mol% | D11: =r2!O5 -> kmol/h | E11: =r2!P5 -> mw | F11: =r2!Q5 -> kg/h | G11: =r2!R5 -> wt% | H11: H_gas at Tin (J/molh) | J11: Temperature for coolin
B12: =r2!M6 -> MAC | C12: =r2!N6 -> 0.7 | D12: =r2!O6 -> 7.5826305 | E12: =r2!P6 -> 70 | F12: =r2!Q6 -> 530.78413 | G12: =r2!R6 -> 1.5557564 | H12: ='gas cooler'!Z8 -> 2.1760319e+08 | J12: =100+273.15 -> 373.15 | O12: PG5 | P12: mol% | Q12: kmol/h | R12: mw | S12: kg/h | T12: wt% | U12: A | V12: B | W12: C | X12: D | Y12: E | Z12: Tout | AA12: Tb | AB12: H_gas at T (J/molh) | AE12: ΔH_gas (J/molh)
B13: =r2!M7 -> CO | C13: =r2!N7 -> 1 | D13: =r2!O7 -> 10.832329 | E13: =r2!P7 -> 28 | F13: =r2!Q7 -> 303.30522 | G13: =r2!R7 -> 0.88900366 | H13: ='gas cooler'!Z9 -> 1.4323959e+08 | O13: MAC | P13: =Q13/$Q$22*100 -> 0.77433651 | Q13: =S13/R13 -> 7.4092424 | R13: =E12 -> 70 | S13: =F12-O30 -> 518.64697 | T13: =S13/$S$22% -> 1.8490845 | U13: ='gas cooler'!U8 -> 14.506 | V13: ='gas cooler'!V8 -> 0.15922 | W13: ='gas cooler'!W8 -> 0.0003118 | X13: ='gas cooler'!X8 -> -4.21e-07 | Y13: ='gas cooler'!Y8 -> 1.4222e-10 | Z13: =$J$12 -> 373.15 | AB13: =Q13*1000*(U13*Z13+V13/2*Z13^2+W13/3*Z13^3+X13/4*Z13^4+Y13/5*Z13^5) -> 1.4865324e+08 | AD13: =H12-AB13 -> 68949949 | AE13: =AD13*-1 -> -68949949
B14: =r2!M8 -> MAA | C14: =r2!N8 -> 2.28 | D14: =r2!O8 -> 24.697711 | E14: =r2!P8 -> 86 | F14: =r2!Q8 -> 2124.0031 | G14: =r2!R8 -> 6.2255656 | H14: ='gas cooler'!Z10 -> 7.2929257e+08 | O14: CO | P14: =Q14/$Q$22*100 -> 1.1320817 | Q14: =S14/R14 -> 10.832329 | R14: =E13 -> 28 | S14: =F13 -> 303.30522 | T14: =S14/$S$22% -> 1.0813463 | U14: ='gas cooler'!U9 -> 29.556 | V14: ='gas cooler'!V9 -> -0.0065807 | W14: ='gas cooler'!W9 -> 2.013e-05 | X14: ='gas cooler'!X9 -> -1.2227e-08 | Y14: ='gas cooler'!Y9 -> 2.6717e-12 | Z14: =$J$12 -> 373.15 | AB14: =Q14*1000*(U14*Z14+V14/2*Z14^2+W14/3*Z14^3+X14/4*Z14^4+Y14/5*Z14^5) -> 1.1768143e+08 | AD14: =H13-AB14 -> 25558161 | AE14: =AD14*-1 -> -25558161
B15: =r2!M9 -> Acetic ac | C15: =r2!N9 -> 0.31 | D15: =r2!O9 -> 3.3580221 | E15: =r2!P9 -> 60 | F15: =r2!Q9 -> 201.48132 | G15: =r2!R9 -> 0.59055243 | H15: ='gas cooler'!Z11 -> 85788936 | O15: Acetone | P15: =Q15/$Q$22*100 -> 0.13584981 | Q15: =S15/R15 -> 1.2998795 | R15: =E16 -> 58 | S15: =F16 -> 75.393011 | T15: =S15/$S$22% -> 0.26879179 | U15: ='gas cooler'!U12 -> 35.918 | V15: ='gas cooler'!V12 -> 0.093896 | W15: ='gas cooler'!W12 -> 0.0001873 | X15: ='gas cooler'!X12 -> -2.1643e-07 | Y15: ='gas cooler'!Y12 -> 6.3174e-11 | Z15: =$J$12 -> 373.15 | AB15: =Q15*1000*(U15*Z15+V15/2*Z15^2+W15/3*Z15^3+X15/4*Z15^4+Y15/5*Z15^5) -> 28891317 | AD15: =H16-AB15 -> 9697194 | AE15: =AD15*-1 -> -9697194
B16: =r2!M10 -> acetone | C16: =r2!N10 -> 0.12 | D16: =r2!O10 -> 1.2998795 | E16: =r2!P10 -> 58 | F16: =r2!Q10 -> 75.393011 | G16: =r2!R10 -> 0.22098091 | H16: ='gas cooler'!Z12 -> 38588511 | O16: acetaldehyde | P16: =Q16/$Q$22*100 -> 0.23773716 | Q16: =S16/R16 -> 2.2747891 | R16: =E17 -> 44 | S16: =F17 -> 100.09072 | T16: =S16/$S$22% -> 0.35684428 | U16: ='gas cooler'!U13 -> 34.14 | V16: ='gas cooler'!V13 -> 0.04002 | W16: ='gas cooler'!W13 -> 0.00015634 | X16: ='gas cooler'!X13 -> 1.6445e-07 | Y16: ='gas cooler'!Y13 -> 4.7248e-11 | Z16: =$J$12 -> 373.15 | AB16: =Q16*1000*(U16*Z16+V16/2*Z16^2+W16/3*Z16^3+X16/4*Z16^4+Y16/5*Z16^5) -> 43445512 | AD16: =H17-AB16 -> 16478981 | AE16: =AD16*-1 -> -16478981
B17: =r2!M11 -> acetaldehyde | C17: =r2!N11 -> 0.21 | D17: =r2!O11 -> 2.2747891 | E17: =r2!P11 -> 44 | F17: =r2!Q11 -> 100.09072 | G17: =r2!R11 -> 0.29337121 | H17: ='gas cooler'!Z13 -> 59924493 | O17: acrolein | P17: =Q17/$Q$22*100 -> 0.045283269 | Q17: =S17/R17 -> 0.43329317 | R17: =E18 -> 56 | S17: =F18 -> 24.264417 | T17: =S17/$S$22% -> 0.086507704 | U17: ='gas cooler'!U14 -> 109.243 | V17: ='gas cooler'!V14 -> -0.50952 | W17: ='gas cooler'!W14 -> 0.0017059 | X17: ='gas cooler'!X14 -> -1.8068e-06 | Y17: ='gas cooler'!Y14 -> 6.5983e-10 | Z17: =$J$12 -> 373.15 | AB17: =Q17*1000*(U17*Z17+V17/2*Z17^2+W17/3*Z17^3+X17/4*Z17^4+Y17/5*Z17^5) -> 11713244 | AD17: =H18-AB17 -> 2835545.5 | AE17: =AD17*-1 -> -2835545.5
